let a=4;
let b=3;
console.log(a+b)
console.log(a+b)
console.log(a+c) //there is an error of undefined
//so we use the try{ } catch{ } ,without it next console can't run or console

//try{
// console.log(a+c)
// } catch(err){   err is the error object
//     console.log(err)
// }
console.log(b)
console.log(a+b)

//asysn-await>> promise chains >> callback hell

//synchronous programming= run as given order and next instruction waits for previous instruction 